<?xml version="1.0" encoding="utf-8"?>
<!-- =================================================================================== -->
<!-- |    This document was autogenerated by xacro from bot.urdf.xacro                 | -->
<!-- |    EDITING THIS FILE BY HAND IS NOT RECOMMENDED                                 | -->
<!-- =================================================================================== -->
<robot name="bot2">
  <link name="base_link"/>
  <link name="base_link_inertia">
    <inertial>
      <origin rpy="0 0 0" xyz="0 0 0"/>
      <mass value="1"/>
      <inertia ixx="0.000538666666667" ixy="0" ixz="0" iyy="0.000538666666667" iyz="0" izz="0.00106666666667"/>
    </inertial>
    <collision>
      <origin rpy="0 0 0" xyz="0 0 0"/>
      <geometry>
        <box size="0.08 0.08 0.008"/>
      </geometry>
    </collision>
    <visual>
      <origin rpy="0 0 0" xyz="0 0 0"/>
      <geometry>
        <box size="0.08 0.08 0.008"/>
      </geometry>
    </visual>
    <!-- caster -->
    <!-- 	<collision name="caster_wheel_collision">
			<origin xyz="${length/2-0.02} 0 -0.02" rpy="0 0 0"/>
			<geometry>
				<sphere radius="${wheel_dia/4.0}"/>
			</geometry>			
			<surface>
		        <friction>
		          <ode>
		            <mu>0</mu>
		            <mu2>0</mu2>
		            <slip1>1.0</slip1>
		            <slip2>1.0</slip2>
		          </ode>
		        </friction>
      		</surface>
		</collision>
		<visual name ="caster_wheel_visual">
			<origin xyz="${length/2-0.02} 0 -0.02" rpy="0 0 0"/>
			<geometry>
				<sphere radius="${wheel_dia/4.0}"/>
			</geometry>
		</visual> -->
  </link>
  <link name="aruco">
    <inertial>
      <origin rpy="0 0 0" xyz="0 0 0"/>
      <mass value="0.04"/>
      <inertia ixx="2.15466666667e-05" ixy="0" ixz="0" iyy="2.15466666667e-05" iyz="0" izz="4.26666666667e-05"/>
    </inertial>
    <collision>
      <origin rpy="0 0 0" xyz="0 0 0"/>
      <geometry>
        <mesh filename="package://bot_description/meshes/bot2.dae" scale="1.25 1.25 1.25"/>
      </geometry>
    </collision>
    <visual>
      <origin rpy="0 0 0" xyz="0 0 0"/>
      <geometry>
        <mesh filename="package://bot_description/meshes/bot2.dae" scale="1.25 1.25 1.25"/>
      </geometry>
    </visual>
  </link>
  <link name="left_wheel">
    <inertial>
      <origin rpy="0 0 0" xyz="0 0 0"/>
      <mass value="0.4"/>
      <inertia ixx="4.21333333333e-05" ixy="0" ixz="0" iyy="4.21333333333e-05" iyz="0" izz="8e-05"/>
    </inertial>
    <collision>
      <origin rpy="0 0 0" xyz="0 0 0"/>
      <geometry>
        <cylinder length="0.008" radius="0.02"/>
      </geometry>
    </collision>
    <visual>
      <origin rpy="0 0 0" xyz="0 0 0"/>
      <geometry>
        <cylinder length="0.008" radius="0.02"/>
      </geometry>
    </visual>
  </link>
  <link name="right_wheel">
    <inertial>
      <origin rpy="0 0 0" xyz="0 0 0"/>
      <mass value="0.4"/>
      <inertia ixx="4.21333333333e-05" ixy="0" ixz="0" iyy="4.21333333333e-05" iyz="0" izz="8e-05"/>
    </inertial>
    <collision>
      <origin rpy="0 0 0" xyz="0 0 0"/>
      <geometry>
        <cylinder length="0.008" radius="0.02"/>
      </geometry>
    </collision>
    <visual>
      <origin rpy="0 0 0" xyz="0 0 0"/>
      <geometry>
        <cylinder length="0.008" radius="0.02"/>
      </geometry>
    </visual>
  </link>
  <link name="left_wheel_dumy">
    <inertial>
      <origin rpy="0 0 0" xyz="0 0 0"/>
      <mass value="0.4"/>
      <inertia ixx="4.21333333333e-05" ixy="0" ixz="0" iyy="4.21333333333e-05" iyz="0" izz="8e-05"/>
    </inertial>
    <collision>
      <origin rpy="0 0 0" xyz="0 0 0"/>
      <geometry>
        <cylinder length="0.008" radius="0.02"/>
      </geometry>
    </collision>
    <visual>
      <origin rpy="0 0 0" xyz="0 0 0"/>
      <geometry>
        <cylinder length="0.008" radius="0.02"/>
      </geometry>
    </visual>
  </link>
  <link name="right_wheel_dumy">
    <inertial>
      <origin rpy="0 0 0" xyz="0 0 0"/>
      <mass value="0.4"/>
      <inertia ixx="4.21333333333e-05" ixy="0" ixz="0" iyy="4.21333333333e-05" iyz="0" izz="8e-05"/>
    </inertial>
    <collision>
      <origin rpy="0 0 0" xyz="0 0 0"/>
      <geometry>
        <cylinder length="0.008" radius="0.02"/>
      </geometry>
    </collision>
    <visual>
      <origin rpy="0 0 0" xyz="0 0 0"/>
      <geometry>
        <cylinder length="0.008" radius="0.02"/>
      </geometry>
    </visual>
  </link>
  <!-- <link name="caster_wheel">
		<inertial>
     		<origin xyz="0 0 0" rpy="0 0 0"/>
     		<mass value="${m_caster_wheel}"/>
     		<inertia ixx="${m_caster_wheel*(2*wheel_dia*wheel_dia/16.0)/5.0}"  ixy="0"  ixz="0" iyy="${m_caster_wheel*(2*wheel_dia*wheel_dia/16.0)/5.0}" iyz="0" izz="${m_caster_wheel*(2*wheel_dia*wheel_dia/16.0)/5.0}" />
   		</inertial>
		<collision>
			<origin xyz="0 0 0" rpy="0 0 0"/>
			<geometry>
				<sphere radius="${wheel_dia/4.0}"/>
			</geometry>			
			<surface>
		        <friction>
		          <ode>
		            <mu>0</mu>
		            <mu2>0</mu2>
		            <slip1>1.0</slip1>
		            <slip2>1.0</slip2>
		          </ode>
		        </friction>
      		</surface>
		</collision>
		<visual>
			<origin xyz="0 0 0" rpy="0 0 0"/>
			<geometry>
				<sphere radius="${wheel_dia/4.0}"/>
			</geometry>
		</visual>
	</link> -->
  <!-- joints def -->
  <joint name="base_link_inertia_joint_2" type="fixed">
    <parent link="base_link"/>
    <child link="base_link_inertia"/>
    <origin rpy="0 0 0" xyz="0 0 0"/>
  </joint>
  <joint name="aruco_joint_2" type="fixed">
    <parent link="base_link"/>
    <child link="aruco"/>
    <origin rpy="0 0 0" xyz="0 0 0.07"/>
  </joint>
  <joint name="bot2_left_wheel_joint" type="continuous">
    <parent link="base_link"/>
    <child link="left_wheel"/>
    <origin rpy="0 1.570795 1.570795" xyz="-0.03 0.048  -0.01"/>
    <axis rpy="0 0 0" xyz="0 0 1"/>
  </joint>
  <joint name="bot2_right_wheel_joint" type="continuous">
    <parent link="base_link"/>
    <child link="right_wheel"/>
    <origin rpy="0 1.570795 1.570795" xyz="-0.03 -0.048  -0.01"/>
    <axis rpy="0 0 0" xyz="0 0 1"/>
  </joint>
  <joint name="bot2_left_wheel_joint_dumy" type="continuous">
    <parent link="base_link"/>
    <child link="left_wheel_dumy"/>
    <origin rpy="0 1.570795 1.570795" xyz="0.03 0.048  -0.01"/>
    <axis rpy="0 0 0" xyz="0 0 1"/>
  </joint>
  <joint name="bot2_right_wheel_joint_dumy" type="continuous">
    <parent link="base_link"/>
    <child link="right_wheel_dumy"/>
    <origin rpy="0 1.570795 1.570795" xyz="0.03 -0.048  -0.01"/>
    <axis rpy="0 0 0" xyz="0 0 1"/>
  </joint>
  <!-- controls plugin for vlecoty based control -->
  <gazebo>
    <plugin filename="libgazebo_ros_diff_drive.so" name="differential_drive_controller">
      <alwaysOn>true</alwaysOn>
      <updateRate>2</updateRate>
      <leftJoint>bot2_left_wheel_joint</leftJoint>
      <rightJoint>bot2_right_wheel_joint</rightJoint>
      <wheelSeparation>0.096</wheelSeparation>
      <wheelDiameter>0.04</wheelDiameter>
      <torque>1</torque>
      <commandTopic>cmd_vel</commandTopic>
      <odometryTopic>odom</odometryTopic>
      <odometryFrame>odom</odometryFrame>
      <robotBaseFrame>base_link</robotBaseFrame>
    </plugin>
  </gazebo>
  <gazebo>
    <plugin filename="libgazebo_ros_diff_drive.so" name="differential_drive_controller">
      <alwaysOn>true</alwaysOn>
      <updateRate>2</updateRate>
      <leftJoint>bot2_left_wheel_joint_dumy</leftJoint>
      <rightJoint>bot2_right_wheel_joint_dumy</rightJoint>
      <wheelSeparation>0.096</wheelSeparation>
      <wheelDiameter>0.04</wheelDiameter>
      <torque>1</torque>
      <commandTopic>cmd_vel_dumy</commandTopic>
      <odometryTopic>odom</odometryTopic>
      <odometryFrame>odom</odometryFrame>
      <robotBaseFrame>base_link</robotBaseFrame>
    </plugin>
  </gazebo>
</robot>
